
<?xml version="1.0" ?>
<robot name="gen3_arm">

    <link name="world"/>


    <link name="table">
      <inertial>
        <origin xyz="0 0 0.5" rpy="0 0 0" />
        <mass value="5.0" />
        <inertia ixx="0.5" ixy="0" ixz="0" iyy="0.5" iyz="0" izz="0.5" />
      </inertial>
      <visual>
        <origin xyz="0 0 0.89" rpy="3.14159 0 0" />
        <geometry>
          <mesh filename="/home/bizon/Sharan/PyBullet_Simulation/meshes/table.obj" scale="0.001 0.001 0.001"/>
        </geometry>
        <material name="">
          <color rgba="0.5 0.5 0.5 1" />
        </material>
      </visual>
      <collision>
        <origin xyz="0 0 0.89" rpy="3.14159 0 0" />
        <geometry>
          <mesh filename="/home/bizon/Sharan/PyBullet_Simulation/meshes/table.obj" scale="0.001 0.001 0.001"/>
        </geometry>
      </collision>
    </link>

    <joint name="table_to_world" type="fixed">
      <origin xyz="0 0 0" rpy="0 0 0" />
      <parent link="world"/>
      <child link="table" />
    </joint>

    <link name="base_link">
      <inertial>
        <origin xyz="-0.000648 -0.000166 0.084487" rpy="0 0 0" />
        <mass value="1.697" />
        <inertia ixx="0.004622" ixy="9E-06" ixz="6E-05" iyy="0.004495" iyz="9E-06" izz="0.002079" />
      </inertial>
      <visual>
        <origin xyz="0 0 0" rpy="0 0 0" />
        <geometry>
          <mesh filename="/home/bizon/Sharan/PyBullet_Simulation/meshes/base_link.dae" />
        </geometry>
        <material name="">
          <color rgba="0.75294 0.75294 0.75294 1" />
        </material>
      </visual>
      <collision>
        <origin xyz="0 0 0" rpy="0 0 0" />
        <geometry>
          <mesh filename="/home/bizon/Sharan/PyBullet_Simulation/meshes/base_link.dae" />
        </geometry>
      </collision>
    </link>

    <joint name="base_joint" type="fixed">
      <origin xyz="0.18 0.4 0.9" rpy="0 0 0" />
      <parent link="table"/>
      <child link="base_link" />
    </joint>

    <link name="shoulder_link">
      <inertial>
        <origin xyz="-2.3E-05 -0.010364 -0.07336" rpy="0 0 0" />
        <mass value="1.3773" />
        <inertia ixx="0.00457" ixy="1E-06" ixz="2E-06" iyy="0.004831" iyz="0.000448" izz="0.001409" />
      </inertial>
      <visual>
        <origin xyz="0 0 0" rpy="0 0 0" />
        <geometry>
          <mesh filename="/home/bizon/Sharan/PyBullet_Simulation/meshes/shoulder_link.dae" />
        </geometry>
        <material name="">
          <color rgba="0.75294 0.75294 0.75294 1" />
        </material>
      </visual>
      <collision>
        <origin xyz="0 0 0" rpy="0 0 0" />
        <geometry>
          <mesh filename="/home/bizon/Sharan/PyBullet_Simulation/meshes/shoulder_link.dae" />
        </geometry>
      </collision>
    </link>

    <joint name="joint_1"
      type="revolute">
        <origin xyz="0 0 0.15643" rpy="3.1416 2.7629E-18 -4.9305E-36" />
        <parent
          link="base_link" />
        <child
          link="shoulder_link" />
        <axis
          xyz="0 0 1" />
        <limit
          lower="-6.283"
          upper="-6.283"
          effort="39"
          velocity="1.3963" />
    </joint>

    <link name="shoulder_link_bounding_box">
      <visual>
        <origin rpy="0 0 0" xyz="0 0 0"/>
        <geometry>
          <mesh filename="/home/bizon/Sharan/PyBullet_Simulation/meshes/shoulder_link_bounding_box.dae"/>
        </geometry>
        <material name="cornflowerblue">
          <color rgba="0.3921 0.5843 0.9294 0.8"/>
        </material>
      </visual>
      <inertial>
        <origin rpy="0 0 0" xyz="0 0 0"/>
        <mass value="1e-10"/>
        <inertia ixx="1e-10" ixy="0" ixz="0" iyy="1e-10" iyz="0" izz="1e-10"/>
      </inertial>
    </link>

    <joint name="joint_1_bounding_box" type="fixed">
      <origin rpy="0 0 0" xyz="0 0 0"/>
      <parent link="shoulder_link"/>
      <child link="shoulder_link_bounding_box"/>
    </joint>


    <link name="half_arm_1_link">
      <inertial>
        <origin xyz="-4.4E-05 -0.09958 -0.013278" rpy="0 0 0" />
        <mass value="1.1636" />
        <inertia ixx="0.011088" ixy="5E-06" ixz="0" iyy="0.001072" iyz="-0.000691" izz="0.011255" />
      </inertial>
      <visual>
        <origin xyz="0 0 0" rpy="0 0 0" />
        <geometry>
          <mesh filename="/home/bizon/Sharan/PyBullet_Simulation/meshes/half_arm_1_link.dae" />
        </geometry>
        <material name="">
          <color rgba="0.75294 0.75294 0.75294 1" />
        </material>
      </visual>
      <collision>
        <origin xyz="0 0 0" rpy="0 0 0" />
        <geometry>
          <mesh filename="/home/bizon/Sharan/PyBullet_Simulation/meshes/half_arm_1_link.dae" />
        </geometry>
      </collision>
    </link>

    <joint
      name="joint_2"
      type="revolute">
      <origin xyz="0 0.005375 -0.12838" rpy="1.5708 2.1343E-17 -1.1102E-16" />
      <parent
        link="shoulder_link" />
      <child
        link="half_arm_1_link" />
      <axis
        xyz="0 0 1" />
      <limit lower="-2.41" upper="2.41" effort="39" velocity="1.3963" />
    </joint>

    <link name="half_arm_1_bounding_box">
      <visual>
        <origin rpy="0 0 0" xyz="0 0 0"/>
        <geometry>
          <mesh filename="/home/bizon/Sharan/PyBullet_Simulation/meshes/half_arm_1_bounding_box_link.dae"/>
        </geometry>
        <material name="cornflowerblue">
          <color rgba="0.3921 0.5843 0.9294 0.8"/>
        </material>
      </visual>
      <inertial>
        <origin rpy="0 0 0" xyz="0 0 0"/>
        <mass value="1e-10"/>
        <inertia ixx="1e-10" ixy="0" ixz="0" iyy="1e-10" iyz="0" izz="1e-10"/>
      </inertial>
    </link>

    <joint name="joint_2_bounding_box" type="fixed">
      <origin rpy="0 0 0" xyz="0 0 0"/>
      <parent link="half_arm_1_link"/>
      <child link="half_arm_1_bounding_box"/>
    </joint>

    <link name="half_arm_2_link">
      <inertial>
        <origin xyz="-4.4E-05 -0.006641 -0.117892" rpy="0 0 0" />
        <mass value="1.1636" />
        <inertia ixx="0.010932" ixy="0" ixz="-7E-06" iyy="0.011127" iyz="0.000606" izz="0.001043" />
      </inertial>
      <visual>
        <origin xyz="0 0 0" rpy="0 0 0" />
        <geometry>
          <mesh filename="/home/bizon/Sharan/PyBullet_Simulation/meshes/half_arm_2_link.dae" />
        </geometry>
        <material name="">
          <color rgba="0.75294 0.75294 0.75294 1" />
        </material>
      </visual>
      <collision>
        <origin xyz="0 0 0" rpy="0 0 0" />
        <geometry>
          <mesh filename="/home/bizon/Sharan/PyBullet_Simulation/meshes/half_arm_2_link.dae" />
        </geometry>
      </collision>
    </link>

    <joint name="joint_3"
        type="revolute">
        <origin xyz="0 -0.21038 -0.006375" rpy="-1.5708 1.2326E-32 -2.9122E-16" />
        <parent
          link="half_arm_1_link" />
        <child
          link="half_arm_2_link" />
        <axis
          xyz="0 0 1" />
        <limit
          lower="-6.283"
          upper="-6.283"
          effort="39"
          velocity="1.3963" />
    </joint>

    <link name="half_arm_2_bounding_box">
      <visual>
        <origin rpy="0 0 0" xyz="0 0 0"/>
        <geometry>
          <mesh filename="/home/bizon/Sharan/PyBullet_Simulation/meshes/half_arm_2_bounding_box_link.dae"/>
        </geometry>
        <material name="cornflowerblue">
          <color rgba="0.3921 0.5843 0.9294 0.8"/>
        </material>
      </visual>
      <inertial>
        <origin rpy="0 0 0" xyz="0 0 0"/>
        <mass value="1e-10"/>
        <inertia ixx="1e-10" ixy="0" ixz="0" iyy="1e-10" iyz="0" izz="1e-10"/>
      </inertial>
    </link>

    <joint name="joint_3_bounding_box" type="fixed">
      <origin rpy="0 0 0" xyz="0 0 0"/>
      <parent link="half_arm_2_link"/>
      <child link="half_arm_2_bounding_box"/>
    </joint>

    <link name="forearm_link">
      <inertial>
        <origin xyz="-1.8E-05 -0.075478 -0.015006" rpy="0 0 0" />
        <mass value="0.9302" />
        <inertia ixx="0.008147" ixy="-1E-06" ixz="0" iyy="0.000631" iyz="-0.0005" izz="0.008316" />
      </inertial>
      <visual>
        <origin xyz="0 0 0" rpy="0 0 0" />
        <geometry>
          <mesh filename="/home/bizon/Sharan/PyBullet_Simulation/meshes/forearm_link.dae" />
        </geometry>
        <material name="">
          <color rgba="0.75294 0.75294 0.75294 1" />
        </material>
      </visual>
      <collision>
        <origin xyz="0 0 0" rpy="0 0 0" />
        <geometry>
          <mesh filename="/home/bizon/Sharan/PyBullet_Simulation/meshes/forearm_link.dae" />
        </geometry>
      </collision>
    </link>

    <joint
      name="joint_4"
      type="revolute">
      <origin xyz="0 0.006375 -0.21038" rpy="1.5708 -6.6954E-17 -1.6653E-16" />
      <parent
        link="half_arm_2_link" />
      <child
        link="forearm_link" />
      <axis
        xyz="0 0 1" />
      <limit lower="-2.66" upper="2.66" effort="39" velocity="1.3963" />
    </joint>

    <link name="forearm_bounding_box">
      <visual>
        <origin rpy="0 0 0" xyz="0 0 0"/>
        <geometry>
          <mesh filename="/home/bizon/Sharan/PyBullet_Simulation/meshes/forearm_bounding_box_link.dae"/>
        </geometry>
        <material name="cornflowerblue">
          <color rgba="0.3921 0.5843 0.9294 0.8"/>
        </material>
      </visual>
      <inertial>
        <origin rpy="0 0 0" xyz="0 0 0"/>
        <mass value="1e-10"/>
        <inertia ixx="1e-10" ixy="0" ixz="0" iyy="1e-10" iyz="0" izz="1e-10"/>
      </inertial>
    </link>

    <joint name="joint_4_bounding_box" type="fixed">
      <origin rpy="0 0 0" xyz="0 0 0"/>
      <parent link="forearm_link"/>
      <child link="forearm_bounding_box"/>
    </joint>

    <link name="spherical_wrist_1_link">
      <inertial>
        <origin xyz="1E-06 -0.009432 -0.063883" rpy="0 0 0" />
        <mass value="0.6781" />
        <inertia ixx="0.001596" ixy="0" ixz="0" iyy="0.001607" iyz="0.000256" izz="0.000399" />
      </inertial>
      <visual>
        <origin xyz="0 0 0" rpy="0 0 0" />
        <geometry>
          <mesh filename="/home/bizon/Sharan/PyBullet_Simulation/meshes/spherical_wrist_1_link.dae" />
        </geometry>
        <material name="">
          <color rgba="0.75294 0.75294 0.75294 1" />
        </material>
      </visual>
      <collision>
        <origin xyz="0 0 0" rpy="0 0 0" />
        <geometry>
          <mesh filename="/home/bizon/Sharan/PyBullet_Simulation/meshes/spherical_wrist_1_link.dae" />
        </geometry>
      </collision>
    </link>

    <joint name="joint_5"
        type="revolute">
        <origin xyz="0 -0.20843 -0.006375" rpy="-1.5708 2.2204E-16 -6.373E-17" />
        <parent
          link="forearm_link" />
        <child
          link="spherical_wrist_1_link" />
        <axis
          xyz="0 0 1" />
        <limit
          lower="-6.283"
          upper="-6.283"
          effort="9"
          velocity="1.2218" />
    </joint>

    <link name="spherical_wrist_1_bounding_box">
      <visual>
        <origin rpy="0 0 0" xyz="0 0 0"/>
        <geometry>
          <mesh filename="/home/bizon/Sharan/PyBullet_Simulation/meshes/spherical_wrist_1_bounding_box_link.dae"/>
        </geometry>
        <material name="cornflowerblue">
          <color rgba="0.3921 0.5843 0.9294 0.8"/>
        </material>
      </visual>
      <inertial>
        <origin rpy="0 0 0" xyz="0 0 0"/>
        <mass value="1e-10"/>
        <inertia ixx="1e-10" ixy="0" ixz="0" iyy="1e-10" iyz="0" izz="1e-10"/>
      </inertial>
    </link>

    <joint name="joint_5_bounding_box" type="fixed">
      <origin rpy="0 0 0" xyz="0 0 0"/>
      <parent link="spherical_wrist_1_link"/>
      <child link="spherical_wrist_1_bounding_box"/>
    </joint>

    <link name="spherical_wrist_2_link">
      <inertial>
        <origin xyz="1E-06 -0.045483 -0.00965" rpy="0 0 0" />
        <mass value="0.6781" />
        <inertia ixx="0.001641" ixy="0" ixz="0" iyy="0.00041" iyz="-0.000278" izz="0.001641" />
      </inertial>
      <visual>
        <origin xyz="0 0 0" rpy="0 0 0" />
        <geometry>
          <mesh filename="/home/bizon/Sharan/PyBullet_Simulation/meshes/spherical_wrist_2_link.dae" />
        </geometry>
        <material name="">
          <color rgba="0.75294 0.75294 0.75294 1" />
        </material>
      </visual>
      <collision>
        <origin xyz="0 0 0" rpy="0 0 0" />
        <geometry>
          <mesh filename="/home/bizon/Sharan/PyBullet_Simulation/meshes/spherical_wrist_2_link.dae" />
        </geometry>
      </collision>
    </link>

    <joint
      name="joint_6"
      type="revolute">
      <origin xyz="0 0.00017505 -0.10593" rpy="1.5708 9.2076E-28 -8.2157E-15" />
      <parent
        link="spherical_wrist_1_link" />
      <child
        link="spherical_wrist_2_link" />
      <axis
        xyz="0 0 1" />
      <limit lower="-2.23" upper="2.23" effort="9" velocity="1.2218" />
    </joint>

    <link name="spherical_wrist_2_bounding_box">
      <visual>
        <origin rpy="0 0 0" xyz="0 0 0"/>
        <geometry>
          <mesh filename="/home/bizon/Sharan/PyBullet_Simulation/meshes/spherical_wrist_2_bounding_box_link.dae"/>
        </geometry>
        <material name="cornflowerblue">
          <color rgba="0.3921 0.5843 0.9294 0.8"/>
        </material>
      </visual>
      <inertial>
        <origin rpy="0 0 0" xyz="0 0 0"/>
        <mass value="1e-10"/>
        <inertia ixx="1e-10" ixy="0" ixz="0" iyy="1e-10" iyz="0" izz="1e-10"/>
      </inertial>
    </link>

    <joint name="joint_6_bounding_box" type="fixed">
      <origin rpy="0 0 0" xyz="0 0 0"/>
      <parent link="spherical_wrist_2_link"/>
      <child link="spherical_wrist_2_bounding_box"/>
    </joint>
    

    <link name="bracelet_link">
      <inertial>
        <origin xyz="0.000281 0.011402 -0.029798" rpy="0 0 0" />
        <mass value="0.5" />
        <inertia ixx="0.000587" ixy="3E-06" ixz="3E-06" iyy="0.000369" iyz="-0.000118" izz="0.000609" />
      </inertial>
      <visual>
        <origin xyz="0 0 0" rpy="0 0 0" />
        <geometry>
          <mesh filename="/home/bizon/Sharan/PyBullet_Simulation/meshes/bracelet_with_vision_link.dae" />
        </geometry>
        <material name="">
          <color rgba="0.75294 0.75294 0.75294 1" />
        </material>
      </visual>
      <collision>
        <origin xyz="0 0 0" rpy="0 0 0" />
        <geometry>
          <mesh filename="/home/bizon/Sharan/PyBullet_Simulation/meshes/bracelet_with_vision_link.dae" />
        </geometry>
      </collision>
    </link>

    <joint
        name="joint_7"
        type="revolute">
        <origin xyz="0 -0.10593 -0.00017505" rpy="-1.5708 -5.5511E-17 9.6396E-17" />
        <parent
          link="spherical_wrist_2_link" />
        <child
          link="bracelet_link" />
        <axis
          xyz="0 0 1" />
        <limit
          lower="-6.283"
          upper="-6.283"
          effort="9"
          velocity="1.2218" />
    </joint>

    <link name="end_effector_link" />
    <joint
      name="end_effector"
      type="fixed">
      <origin xyz="0 0 -0.0615250000000001" rpy="3.14159265358979 1.09937075168372E-32 0" />
      <parent
        link="bracelet_link" />
      <child
        link="end_effector_link" />
      <axis
        xyz="0 0 0" />
    </joint>

    <link name="camera_link">
      <visual>
        <origin xyz="0 0 0" rpy="0 0 0" />
        <geometry>
          <box size="0.02 0.02 0.02"/>
        </geometry>
        <material name="black">
          <color rgba="0 0 0 1"/>
        </material>
      </visual>
    </link>

    <joint name="camera_module" type="fixed">
      <origin xyz="0 0.05639 0.01305" rpy="0 -1.5708 -1.5708" />
      <parent link="end_effector_link"/>
      <child link="camera_link"/>
    </joint>

    <link name="camera_depth_frame" />
    <joint name="depth_module" type="fixed">
      <origin xyz="0.0275 0.066 0.01305" rpy="0 -1.5708 -1.5708" />
      <parent link="end_effector_link"/>
      <child link="camera_depth_frame"/>
    </joint>

    <link name="camera_color_frame" />
    <joint name="color_module" type="fixed">
      <origin xyz="0 0.05639 0.01305" rpy="0 -1.5708 -1.5708" />
      <parent link="end_effector_link"/>
      <child link="camera_color_frame"/>
    </joint>

    <link name="robotiq_85_base_link">
      <visual>
        <geometry>
          <mesh filename="/home/bizon/Sharan/PyBullet_Simulation/meshes_1/visual/robotiq_85_base_link.dae"/>
        </geometry>
      </visual>
      <collision>
        <geometry>
          <mesh filename="/home/bizon/Sharan/PyBullet_Simulation/meshes_1/collision/robotiq_85_base_link.stl"/>
        </geometry>
      </collision>
      <inertial>
        <mass value="0.636951" />
        <origin xyz="0.0 0.0 0.0" />
        <inertia ixx = "0.000380" ixy = "0.000000" ixz = "0.000000"
             iyx = "0.000000" iyy = "0.001110" iyz = "0.000000"
             izx = "0.000000" izy = "0.000000" izz = "0.001171" />
      </inertial>
    </link>

    <joint name="robotiq_85_base_joint" type="fixed">
        <parent link="end_effector_link" />
        <child link="robotiq_85_base_link" />
        <origin xyz = "0 0 0" rpy="0 -1.57 0"/>
    </joint>

    <link name="EE_bounding_box">
      <visual>
        <origin rpy="0 0 0" xyz="0 0 0"/>
        <geometry>
          <mesh filename="/home/bizon/Sharan/PyBullet_Simulation/meshes/End_effector_bounding_box_link.dae"/>
        </geometry>
        <material name="cornflowerblue">
          <color rgba="0.3921 0.5843 0.9294 0.8"/>
        </material>
      </visual>
      <inertial>
        <origin rpy="0 0 0" xyz="0 0 0"/>
        <mass value="1e-10"/>
        <inertia ixx="1e-10" ixy="0" ixz="0" iyy="1e-10" iyz="0" izz="1e-10"/>
      </inertial>
    </link>

    <joint name="EE_joint_bounding_box" type="fixed">
      <origin rpy="0 0 0" xyz="0.06 0 0"/>
      <parent link="robotiq_85_base_link"/>
      <child link="EE_bounding_box"/>
    </joint>

    <joint name="robotiq_85_left_knuckle_joint" type="revolute">
      <parent link="robotiq_85_base_link"/>
      <child link="robotiq_85_left_knuckle_link"/>
      <axis xyz="0 0 1"/>
      <origin rpy="3.14 0.0 0.0" xyz="0.05490451627 0.03060114443 0.0"/>
      <limit lower="0.0" upper="0.80285" velocity="3.14" effort="1000"/>
    </joint>

    <joint name="robotiq_85_right_knuckle_joint" type="revolute">
      <parent link="robotiq_85_base_link"/>
      <child link="robotiq_85_right_knuckle_link"/>
      <axis xyz="0 0 1"/>
      <origin rpy="0.0 0.0 0.0" xyz="0.05490451627 -0.03060114443 0.0"/>
      <limit lower="-3.14" upper="3.14" velocity="3.14" effort="1000"/>
      <mimic joint="robotiq_85_left_knuckle_joint"/>
    </joint>

    <link name="robotiq_85_left_knuckle_link">
      <visual>
        <geometry>
          <mesh filename="/home/bizon/Sharan/PyBullet_Simulation/meshes_1/visual/robotiq_85_knuckle_link.dae"/>
        </geometry>
      </visual>
      <collision>
        <geometry>
          <mesh filename="/home/bizon/Sharan/PyBullet_Simulation/meshes_1/collision/robotiq_85_knuckle_link.stl"/>
        </geometry>
      </collision>
      <inertial>
        <mass value="0.018491" />
        <origin xyz="0.0 0.0 0.0" />
        <inertia ixx = "0.000009" ixy = "-0.000001" ixz = "0.000000"
             iyx = "-0.000001" iyy = "0.000001" iyz = "0.000000"
             izx = "0.000000" izy = "0.000000" izz = "0.000010" />
      </inertial>
    </link>

    <link name="robotiq_85_right_knuckle_link">
      <visual>
        <geometry>
          <mesh filename="/home/bizon/Sharan/PyBullet_Simulation/meshes_1/visual/robotiq_85_knuckle_link.dae"/>
        </geometry>
      </visual>
      <collision>
        <geometry>
          <mesh filename="/home/bizon/Sharan/PyBullet_Simulation/meshes_1/collision/robotiq_85_knuckle_link.stl"/>
        </geometry>
      </collision>
      <inertial>
        <mass value="0.018491" />
        <origin xyz="0.0 0.0 0.0" />
        <inertia ixx = "0.000009" ixy = "-0.000001" ixz = "0.000000"
             iyx = "-0.000001" iyy = "0.000001" iyz = "0.000000"
             izx = "0.000000" izy = "0.000000" izz = "0.000010" />
      </inertial>
    </link>

    <joint name="robotiq_85_left_finger_joint" type="fixed">
      <parent link="robotiq_85_left_knuckle_link"/>
      <child link="robotiq_85_left_finger_link"/>
      <origin xyz="-0.00408552455 -0.03148604435 0.0" rpy="0 0 0" />
    </joint>

    <joint name="robotiq_85_right_finger_joint" type="fixed">
      <parent link="robotiq_85_right_knuckle_link"/>
      <child link="robotiq_85_right_finger_link"/>
      <origin xyz="-0.00408552455 -0.03148604435 0.0" rpy="0 0 0" />
    </joint>

    <link name="robotiq_85_left_finger_link">
      <visual>
        <geometry>
          <mesh filename="/home/bizon/Sharan/PyBullet_Simulation/meshes_1/visual/robotiq_85_finger_link.dae"/>
        </geometry>
      </visual>
      <collision>
        <geometry>
          <mesh filename="/home/bizon/Sharan/PyBullet_Simulation/meshes_1/collision/robotiq_85_finger_link.stl"/>
        </geometry>
      </collision>
      <inertial>
        <mass value="0.027309" />
        <origin xyz="0.0 0.0 0.0" />
        <inertia ixx = "0.000003" ixy = "-0.000002" ixz = "0.000000"
             iyx = "-0.000002" iyy = "0.000021" iyz = "0.000000"
             izx = "0.000000" izy = "0.000000" izz = "0.000020" />
      </inertial>
    </link>

    <link name="robotiq_85_right_finger_link">
      <visual>
        <geometry>
          <mesh filename="/home/bizon/Sharan/PyBullet_Simulation/meshes_1/visual/robotiq_85_finger_link.dae"/>
        </geometry>
      </visual>
      <collision>
        <geometry>
          <mesh filename="/home/bizon/Sharan/PyBullet_Simulation/meshes_1/collision/robotiq_85_finger_link.stl"/>
        </geometry>
      </collision>
      <inertial>
        <mass value="0.027309" />
        <origin xyz="0.0 0.0 0.0" />
        <inertia ixx = "0.000003" ixy = "-0.000002" ixz = "0.000000"
             iyx = "-0.000002" iyy = "0.000021" iyz = "0.000000"
             izx = "0.000000" izy = "0.000000" izz = "0.000020" />
      </inertial>
    </link>

    <joint name="robotiq_85_left_inner_knuckle_joint" type="revolute">
      <parent link="robotiq_85_base_link"/>
      <child link="robotiq_85_left_inner_knuckle_link"/>
      <axis xyz="0 0 1"/>
      <origin xyz="0.06142 0.0127 0" rpy="3.14 0.0 0.0" />
      <limit lower="-3.14" upper="3.14" velocity="3.14" effort="0.1"/>
      <mimic joint="robotiq_85_left_knuckle_joint" offset="0"/>
    </joint>

    <joint name="robotiq_85_right_inner_knuckle_joint" type="revolute">
      <parent link="robotiq_85_base_link"/>
      <child link="robotiq_85_right_inner_knuckle_link"/>
      <axis xyz="0 0 1"/>
      <origin xyz="0.06142 -0.0127 0" rpy="0 0 0"/>
      <limit lower="-3.14" upper="3.14" velocity="3.14" effort="0.1"/>
      <mimic joint="robotiq_85_left_knuckle_joint" offset="0"/>
    </joint>

    <link name="robotiq_85_left_inner_knuckle_link">
      <visual>
        <geometry>
          <mesh filename="/home/bizon/Sharan/PyBullet_Simulation/meshes_1/visual/robotiq_85_inner_knuckle_link.dae"/>
        </geometry>
      </visual>
      <collision>
        <geometry>
          <mesh filename="/home/bizon/Sharan/PyBullet_Simulation/meshes_1/collision/robotiq_85_inner_knuckle_link.stl"/>
        </geometry>
      </collision>
      <inertial>
        <mass value="0.029951" />
        <origin xyz="0.0 0.0 0.0" />
        <inertia ixx = "0.000039" ixy = "0.000000" ixz = "0.000000"
             iyx = "0.000000" iyy = "0.000005" iyz = "0.000000"
             izx = "0.000000" izy = "0.000000" izz = "0.000035" />
      </inertial>
    </link>
    <link name="robotiq_85_right_inner_knuckle_link">
      <visual>
        <geometry>
          <mesh filename="/home/bizon/Sharan/PyBullet_Simulation/meshes_1/visual/robotiq_85_inner_knuckle_link.dae"/>
        </geometry>
      </visual>
      <collision>
        <geometry>
          <mesh filename="/home/bizon/Sharan/PyBullet_Simulation/meshes_1/collision/robotiq_85_inner_knuckle_link.stl"/>
        </geometry>
      </collision>
      <inertial>
        <mass value="0.029951" />
        <origin xyz="0.0 0.0 0.0" />
        <inertia ixx = "0.000039" ixy = "0.000000" ixz = "0.000000"
             iyx = "0.000000" iyy = "0.000005" iyz = "0.000000"
             izx = "0.000000" izy = "0.000000" izz = "0.000035" />
      </inertial>
    </link>

    <joint name="robotiq_85_left_finger_tip_joint" type="revolute">
      <parent link="robotiq_85_left_inner_knuckle_link"/>
      <child link="robotiq_85_left_finger_tip_link"/>
      <axis xyz="0 0 1"/>
      <origin xyz="0.04303959807 -0.03759940821 0.0" rpy="0.0 0.0 0.0"/>
      <limit lower="-3.14" upper="3.14" velocity="3.14" effort="0.1"/>
      <mimic joint="robotiq_85_left_knuckle_joint" multiplier="-1"/>
    </joint>

    <joint name="robotiq_85_right_finger_tip_joint" type="revolute">
      <parent link="robotiq_85_right_inner_knuckle_link"/>
      <child link="robotiq_85_right_finger_tip_link"/>
      <axis xyz="0 0 1"/>
      <origin rpy="0.0 0.0 0.0" xyz="0.04303959807 -0.03759940821  0.0"/>
      <limit lower="-3.14" upper="3.14" velocity="3.14" effort="0.1"/>
      <mimic joint="robotiq_85_left_knuckle_joint" multiplier="-1"/>
    </joint>


    <link name="robotiq_85_left_finger_tip_link">
      <visual>
        <geometry>
          <mesh filename="/home/bizon/Sharan/PyBullet_Simulation/meshes_1/visual/robotiq_85_finger_tip_link.dae"/>
        </geometry>
      </visual>
      <collision>
        <geometry>
          <mesh filename="/home/bizon/Sharan/PyBullet_Simulation/meshes_1/collision/robotiq_85_finger_tip_link.stl"/>
        </geometry>
      </collision>
      <inertial>
        <mass value="0.019555" />
        <origin xyz="0.0 0.0 0.0" />
        <inertia ixx = "0.000002" ixy = "0.000000" ixz = "0.000000"
             iyx = "0.000000" iyy = "0.000005" iyz = "0.000000"
             izx = "0.000000" izy = "0.000000" izz = "0.000006" />
      </inertial>
    </link>

    <link name="robotiq_85_right_finger_tip_link">
      <visual>
        <geometry>
          <mesh filename="/home/bizon/Sharan/PyBullet_Simulation/meshes_1/visual/robotiq_85_finger_tip_link.dae"/>
        </geometry>
      </visual>
      <collision>
        <geometry>
          <mesh filename="/home/bizon/Sharan/PyBullet_Simulation/meshes_1/collision/robotiq_85_finger_tip_link.stl"/>
        </geometry>
      </collision>
      <inertial>
        <mass value="0.019555" />
        <origin xyz="0.0 0.0 0.0" />
        <inertia ixx = "0.000002" ixy = "0.000000" ixz = "0.000000"
             iyx = "0.000000" iyy = "0.000005" iyz = "0.000000"
             izx = "0.000000" izy = "0.000000" izz = "0.000006" />
      </inertial>
    </link>
</robot>